<?xml version="1.0" ?>
<!-- =================================================================================== -->
<!-- |    This document was autogenerated by xacro from ele.xacro                      | -->
<!-- |    EDITING THIS FILE BY HAND IS NOT RECOMMENDED                                 | -->
<!-- =================================================================================== -->
<robot name="me">
  <!-- fixed frame and link without xacro -->
  <link name="map"/>
  <joint name="fixed" type="fixed">
    <parent link="map"/>
    <child link="chassis"/>
    <origin rpy="1.57 0 0" xyz="0.0 0.0 0.0"/>
  </joint>
  <link name="chassis">
    <collision>
      <origin rpy="0.0 0.0 0.0" xyz="0.0 0.0 0.0"/>
      <geometry>
        <box size="10.0 10.0 0.5"/>
      </geometry>
    </collision>
    <visual>
      <origin rpy="0.0 0.0 0.0" xyz="0.0 0.0 0.0"/>
      <geometry>
        <box size="10.0 0.5 10"/>
      </geometry>
    </visual>
    <inertial>
      <mass value="10"/>
      <inertia ixx="1" ixy="0" ixz="0" iyy="1" iyz="0" izz="1"/>
    </inertial>
  </link>
  <joint name="hip_1" type="continuous">
    <parent link="chassis"/>
    <child link="thigh_1"/>
    <axis xyz="0 0 1"/>
    <origin rpy="0 0 0" xyz="-5 0 5"/>
  </joint>
  <joint name="knee_1" type="revolute">
    <parent link="thigh_1"/>
    <child link="calf_1"/>
    <axis xyz="0 0 1"/>
    <limit effort="1000.0" lower="-3.14159" upper="3.14159" velocity="50.0"/>
    <origin rpy="0 0 0" xyz="6 0 0"/>
  </joint>
  <joint name="ankle_1" type="revolute">
    <parent link="calf_1"/>
    <child link="foot_1"/>
    <axis xyz="0 0 1"/>
    <limit effort="1000.0" lower="-3.14159" upper="3.14159" velocity="50.0"/>
    <origin rpy="0 0 0" xyz="4 0 0"/>
  </joint>
  <link name="thigh_1">
    <collision>
      <origin rpy="0 1.57 0" xyz="3 0 0"/>
      <geometry>
        <cylinder length="6" radius="0.25"/>
      </geometry>
    </collision>
    <visual>
      <origin rpy="0 1.57 0" xyz="3 0 0"/>
      <geometry>
        <cylinder length="6" radius="0.25"/>
      </geometry>
    </visual>
    <inertial>
      <mass value="10"/>
      <inertia ixx="1" ixy="0" ixz="0" iyy="1" iyz="0" izz="1"/>
    </inertial>
  </link>
  <link name="calf_1">
    <collision>
      <origin rpy="0 1.57 0.0" xyz="2 0 0.0"/>
      <geometry>
        <cylinder length="4" radius="0.25"/>
      </geometry>
    </collision>
    <visual>
      <origin rpy="0 1.57 0.0" xyz="2 0 0.0"/>
      <geometry>
        <cylinder length="4" radius="0.25"/>
      </geometry>
    </visual>
    <visual>
      <origin rpy="0.0 0.0 0.0" xyz="0 0 0.0"/>
      <geometry>
        <sphere radius="0.5"/>
      </geometry>
    </visual>
    <inertial>
      <mass value="10"/>
      <inertia ixx="1" ixy="0" ixz="0" iyy="1" iyz="0" izz="1"/>
    </inertial>
  </link>
  <link name="foot_1">
    <collision>
      <origin rpy="0.0 1.57 0.0" xyz="1 0 0.0"/>
      <geometry>
        <cylinder length="2" radius="0.25"/>
      </geometry>
    </collision>
    <visual>
      <origin rpy="0.0 1.57 0.0" xyz="1 0 0.0"/>
      <geometry>
        <cylinder length="2" radius="0.25"/>
      </geometry>
    </visual>
    <visual>
      <origin rpy="0.0 0.0 0.0" xyz="0 0 0.0"/>
      <geometry>
        <sphere radius="0.5"/>
      </geometry>
    </visual>
    <inertial>
      <mass value="10"/>
      <inertia ixx="1" ixy="0" ixz="0" iyy="1" iyz="0" izz="1"/>
    </inertial>
  </link>
  <joint name="hip_2" type="continuous">
    <parent link="chassis"/>
    <child link="thigh_2"/>
    <axis xyz="0 0 1"/>
    <origin rpy="0 0 0" xyz="5 0 5"/>
  </joint>
  <joint name="knee_2" type="revolute">
    <parent link="thigh_2"/>
    <child link="calf_2"/>
    <axis xyz="0 0 1"/>
    <limit effort="1000.0" lower="-3.14159" upper="3.14159" velocity="50.0"/>
    <origin rpy="0 0 0" xyz="6 0 0"/>
  </joint>
  <joint name="ankle_2" type="revolute">
    <parent link="calf_2"/>
    <child link="foot_2"/>
    <axis xyz="0 0 1"/>
    <limit effort="1000.0" lower="-3.14159" upper="3.14159" velocity="50.0"/>
    <origin rpy="0 0 0" xyz="4 0 0"/>
  </joint>
  <link name="thigh_2">
    <collision>
      <origin rpy="0 1.57 0" xyz="3 0 0"/>
      <geometry>
        <cylinder length="6" radius="0.25"/>
      </geometry>
    </collision>
    <visual>
      <origin rpy="0 1.57 0" xyz="3 0 0"/>
      <geometry>
        <cylinder length="6" radius="0.25"/>
      </geometry>
    </visual>
    <inertial>
      <mass value="10"/>
      <inertia ixx="1" ixy="0" ixz="0" iyy="1" iyz="0" izz="1"/>
    </inertial>
  </link>
  <link name="calf_2">
    <collision>
      <origin rpy="0 1.57 0.0" xyz="2 0 0.0"/>
      <geometry>
        <cylinder length="4" radius="0.25"/>
      </geometry>
    </collision>
    <visual>
      <origin rpy="0 1.57 0.0" xyz="2 0 0.0"/>
      <geometry>
        <cylinder length="4" radius="0.25"/>
      </geometry>
    </visual>
    <visual>
      <origin rpy="0.0 0.0 0.0" xyz="0 0 0.0"/>
      <geometry>
        <sphere radius="0.5"/>
      </geometry>
    </visual>
    <inertial>
      <mass value="10"/>
      <inertia ixx="1" ixy="0" ixz="0" iyy="1" iyz="0" izz="1"/>
    </inertial>
  </link>
  <link name="foot_2">
    <collision>
      <origin rpy="0.0 1.57 0.0" xyz="1 0 0.0"/>
      <geometry>
        <cylinder length="2" radius="0.25"/>
      </geometry>
    </collision>
    <visual>
      <origin rpy="0.0 1.57 0.0" xyz="1 0 0.0"/>
      <geometry>
        <cylinder length="2" radius="0.25"/>
      </geometry>
    </visual>
    <visual>
      <origin rpy="0.0 0.0 0.0" xyz="0 0 0.0"/>
      <geometry>
        <sphere radius="0.5"/>
      </geometry>
    </visual>
    <inertial>
      <mass value="10"/>
      <inertia ixx="1" ixy="0" ixz="0" iyy="1" iyz="0" izz="1"/>
    </inertial>
  </link>
  <joint name="hip_3" type="continuous">
    <parent link="chassis"/>
    <child link="thigh_3"/>
    <axis xyz="0 0 1"/>
    <origin rpy="0 0 0" xyz="-5 0 -5"/>
  </joint>
  <joint name="knee_3" type="revolute">
    <parent link="thigh_3"/>
    <child link="calf_3"/>
    <axis xyz="0 0 1"/>
    <limit effort="1000.0" lower="-3.14159" upper="3.14159" velocity="50.0"/>
    <origin rpy="0 0 0" xyz="6 0 0"/>
  </joint>
  <joint name="ankle_3" type="revolute">
    <parent link="calf_3"/>
    <child link="foot_3"/>
    <axis xyz="0 0 1"/>
    <limit effort="1000.0" lower="-3.14159" upper="3.14159" velocity="50.0"/>
    <origin rpy="0 0 0" xyz="4 0 0"/>
  </joint>
  <link name="thigh_3">
    <collision>
      <origin rpy="0 1.57 0" xyz="3 0 0"/>
      <geometry>
        <cylinder length="6" radius="0.25"/>
      </geometry>
    </collision>
    <visual>
      <origin rpy="0 1.57 0" xyz="3 0 0"/>
      <geometry>
        <cylinder length="6" radius="0.25"/>
      </geometry>
    </visual>
    <inertial>
      <mass value="10"/>
      <inertia ixx="1" ixy="0" ixz="0" iyy="1" iyz="0" izz="1"/>
    </inertial>
  </link>
  <link name="calf_3">
    <collision>
      <origin rpy="0 1.57 0.0" xyz="2 0 0.0"/>
      <geometry>
        <cylinder length="4" radius="0.25"/>
      </geometry>
    </collision>
    <visual>
      <origin rpy="0 1.57 0.0" xyz="2 0 0.0"/>
      <geometry>
        <cylinder length="4" radius="0.25"/>
      </geometry>
    </visual>
    <visual>
      <origin rpy="0.0 0.0 0.0" xyz="0 0 0.0"/>
      <geometry>
        <sphere radius="0.5"/>
      </geometry>
    </visual>
    <inertial>
      <mass value="10"/>
      <inertia ixx="1" ixy="0" ixz="0" iyy="1" iyz="0" izz="1"/>
    </inertial>
  </link>
  <link name="foot_3">
    <collision>
      <origin rpy="0.0 1.57 0.0" xyz="1 0 0.0"/>
      <geometry>
        <cylinder length="2" radius="0.25"/>
      </geometry>
    </collision>
    <visual>
      <origin rpy="0.0 1.57 0.0" xyz="1 0 0.0"/>
      <geometry>
        <cylinder length="2" radius="0.25"/>
      </geometry>
    </visual>
    <visual>
      <origin rpy="0.0 0.0 0.0" xyz="0 0 0.0"/>
      <geometry>
        <sphere radius="0.5"/>
      </geometry>
    </visual>
    <inertial>
      <mass value="10"/>
      <inertia ixx="1" ixy="0" ixz="0" iyy="1" iyz="0" izz="1"/>
    </inertial>
  </link>
  <joint name="hip_4" type="continuous">
    <parent link="chassis"/>
    <child link="thigh_4"/>
    <axis xyz="0 0 1"/>
    <origin rpy="0 0 0" xyz="5 0 -5"/>
  </joint>
  <joint name="knee_4" type="revolute">
    <parent link="thigh_4"/>
    <child link="calf_4"/>
    <axis xyz="0 0 1"/>
    <limit effort="1000.0" lower="-3.14159" upper="3.14159" velocity="50.0"/>
    <origin rpy="0 0 0" xyz="6 0 0"/>
  </joint>
  <joint name="ankle_4" type="revolute">
    <parent link="calf_4"/>
    <child link="foot_4"/>
    <axis xyz="0 0 1"/>
    <limit effort="1000.0" lower="-3.14159" upper="3.14159" velocity="50.0"/>
    <origin rpy="0 0 0" xyz="4 0 0"/>
  </joint>
  <link name="thigh_4">
    <collision>
      <origin rpy="0 1.57 0" xyz="3 0 0"/>
      <geometry>
        <cylinder length="6" radius="0.25"/>
      </geometry>
    </collision>
    <visual>
      <origin rpy="0 1.57 0" xyz="3 0 0"/>
      <geometry>
        <cylinder length="6" radius="0.25"/>
      </geometry>
    </visual>
    <inertial>
      <mass value="10"/>
      <inertia ixx="1" ixy="0" ixz="0" iyy="1" iyz="0" izz="1"/>
    </inertial>
  </link>
  <link name="calf_4">
    <collision>
      <origin rpy="0 1.57 0.0" xyz="2 0 0.0"/>
      <geometry>
        <cylinder length="4" radius="0.25"/>
      </geometry>
    </collision>
    <visual>
      <origin rpy="0 1.57 0.0" xyz="2 0 0.0"/>
      <geometry>
        <cylinder length="4" radius="0.25"/>
      </geometry>
    </visual>
    <visual>
      <origin rpy="0.0 0.0 0.0" xyz="0 0 0.0"/>
      <geometry>
        <sphere radius="0.5"/>
      </geometry>
    </visual>
    <inertial>
      <mass value="10"/>
      <inertia ixx="1" ixy="0" ixz="0" iyy="1" iyz="0" izz="1"/>
    </inertial>
  </link>
  <link name="foot_4">
    <collision>
      <origin rpy="0.0 1.57 0.0" xyz="1 0 0.0"/>
      <geometry>
        <cylinder length="2" radius="0.25"/>
      </geometry>
    </collision>
    <visual>
      <origin rpy="0.0 1.57 0.0" xyz="1 0 0.0"/>
      <geometry>
        <cylinder length="2" radius="0.25"/>
      </geometry>
    </visual>
    <visual>
      <origin rpy="0.0 0.0 0.0" xyz="0 0 0.0"/>
      <geometry>
        <sphere radius="0.5"/>
      </geometry>
    </visual>
    <inertial>
      <mass value="10"/>
      <inertia ixx="1" ixy="0" ixz="0" iyy="1" iyz="0" izz="1"/>
    </inertial>
  </link>
</robot>
