<?xml version="1.0" ?>
<!-- =================================================================================== -->
<!-- |    This document was autogenerated by xacro from ele.xacro                      | -->
<!-- |    EDITING THIS FILE BY HAND IS NOT RECOMMENDED                                 | -->
<!-- =================================================================================== -->
<robot name="me">
  <!-- fixed frame and link without xacro -->
  <link name="map"/>
  <joint name="fixed" type="fixed">
    <parent link="map"/>
    <child link="chassis"/>
    <origin rpy="1.57 0 0" xyz="0.0 0.0 0.0"/>
  </joint>
  <link name="chassis">
    <collision>
      <origin rpy="0.0 0.0 0.0" xyz="0.0 0.0 0.0"/>
      <geometry>
        <box size="10.0 10.0 0.5"/>
      </geometry>
    </collision>
    <visual>
      <origin rpy="0.0 0.0 0.0" xyz="0.0 0.0 0.0"/>
      <geometry>
        <box size="10.0 0.5 10"/>
      </geometry>
    </visual>
    <inertial>
      <mass value="1000"/>
      <inertia ixx="100" ixy="0" ixz="0" iyy="100" iyz="0" izz="100"/>
    </inertial>
  </link>
  <!-- Joints -->
  <joint name="hip_1" type="continuous">
    <parent link="chassis"/>
    <child link="thigh_1"/>
    <axis xyz="0 0 1"/>
    <origin rpy="0 0 0" xyz="-5 0 5"/>
    <limit effort="5" lower="-3.14159" upper="3.14159" velocity="1.0"/>
  </joint>
  <joint name="knee_1" type="revolute">
    <parent link="thigh_1"/>
    <child link="calf_1"/>
    <axis xyz="0 0 1"/>
    <!-- <limit lower="-3.14159" upper="3.14159" velocity="50.0" effort="1000.0"/> -->
    <limit effort="5" lower="-3.14159" upper="3.14159" velocity="1.0"/>
    <origin rpy="0 0 0" xyz="6 0 0"/>
  </joint>
  <joint name="ankle_1" type="revolute">
    <parent link="calf_1"/>
    <child link="foot_1"/>
    <axis xyz="0 0 1"/>
    <limit effort="5" lower="-3.14159" upper="3.14159" velocity="1.0"/>
    <origin rpy="0 0 0" xyz="4 0 0"/>
  </joint>
  <!-- Transmissions -->
  <transmission name="hip_trans_1">
    <type>transmission_interface/SimpleTransmission</type>
    <actuator name="hip_motor_1">
      <mechanicalReduction>1</mechanicalReduction>
    </actuator>
    <joint name="hip_1">
      <hardwareInterface>hardware_interface/PositionJointInterface</hardwareInterface>
    </joint>
  </transmission>
  <transmission name="knee_trans_1">
    <type>transmission_interface/SimpleTransmission</type>
    <actuator name="knee_motor_1">
      <mechanicalReduction>1</mechanicalReduction>
    </actuator>
    <joint name="knee_1">
      <hardwareInterface>hardware_interface/PositionJointInterface</hardwareInterface>
    </joint>
  </transmission>
  <transmission name="ankle_trans_1">
    <type>transmission_interface/SimpleTransmission</type>
    <actuator name="ankle_motor_1">
      <mechanicalReduction>1</mechanicalReduction>
    </actuator>
    <joint name="ankle_1">
      <hardwareInterface>hardware_interface/PositionJointInterface</hardwareInterface>
    </joint>
  </transmission>
  <!-- Links -->
  <link name="thigh_1">
    <collision>
      <origin rpy="0 1.57 0" xyz="3 0 0"/>
      <geometry>
        <cylinder length="6" radius="0.25"/>
      </geometry>
    </collision>
    <visual>
      <origin rpy="0 1.57 0" xyz="3 0 0"/>
      <geometry>
        <cylinder length="6" radius="0.25"/>
      </geometry>
    </visual>
    <inertial>
      <mass value="10"/>
      <inertia ixx="1" ixy="0" ixz="0" iyy="1" iyz="0" izz="1"/>
    </inertial>
  </link>
  <link name="calf_1">
    <collision>
      <origin rpy="0 1.57 0.0" xyz="2 0 0.0"/>
      <geometry>
        <cylinder length="4" radius="0.25"/>
      </geometry>
    </collision>
    <visual>
      <origin rpy="0 1.57 0.0" xyz="2 0 0.0"/>
      <geometry>
        <cylinder length="4" radius="0.25"/>
      </geometry>
    </visual>
    <visual>
      <origin rpy="0.0 0.0 0.0" xyz="0 0 0.0"/>
      <geometry>
        <sphere radius="0.5"/>
      </geometry>
    </visual>
    <inertial>
      <mass value="10"/>
      <inertia ixx="1" ixy="0" ixz="0" iyy="1" iyz="0" izz="1"/>
    </inertial>
  </link>
  <link name="foot_1">
    <collision>
      <origin rpy="0.0 1.57 0.0" xyz="1 0 0.0"/>
      <geometry>
        <cylinder length="2" radius="0.25"/>
      </geometry>
    </collision>
    <visual>
      <origin rpy="0.0 1.57 0.0" xyz="1 0 0.0"/>
      <geometry>
        <cylinder length="2" radius="0.25"/>
      </geometry>
    </visual>
    <visual>
      <origin rpy="0.0 0.0 0.0" xyz="0 0 0.0"/>
      <geometry>
        <sphere radius="0.5"/>
      </geometry>
    </visual>
    <inertial>
      <mass value="10"/>
      <inertia ixx="1" ixy="0" ixz="0" iyy="1" iyz="0" izz="1"/>
    </inertial>
  </link>
  <gazebo reference="foot_1">
    <mu1 value="200.0"/>
    <mu2 value="100.0"/>
    <kp value="10000000.0"/>
    <kd value="1.0"/>
    <material>Gazebo/Grey</material>
  </gazebo>
  <!-- <xacro:leg leg_no='2'>
        <origin xyz="5 0 5" rpy="0 0 0"/>
    </xacro:leg>
    <xacro:leg leg_no='3'>
        <origin xyz="-5 0 -5" rpy="0 0 0"/>
    </xacro:leg>
    <xacro:leg leg_no='4'>
        <origin xyz="5 0 -5" rpy="0 0 0"/>
    </xacro:leg> -->
  <gazebo>
    <plugin filename="libgazebo_ros_control.so" name="gazebo_ros_control">
      <robotNamespace>/</robotNamespace>
    </plugin>
  </gazebo>
</robot>
