<?xml version="1.0"?>
<robot xmlns:xacro="http://www.ros.org/wiki/xacro" name="me">
    
    <!-- Xacro defn for a leg -->
    <xacro:macro name="leg" params="leg_no *origin">
        <!-- Joints -->
        <joint name="hip_${leg_no}" type="continuous">
            <parent link="chassis"/>
            <child link="thigh_${leg_no}"/>
            <axis xyz="0 0 1"/>
            <xacro:insert_block name="origin" />
            <limit effort="5" velocity="1.0" lower="-3.14159" upper="3.14159"/>

        </joint>
        <joint name="knee_${leg_no}" type="revolute">
            <parent link="thigh_${leg_no}"/>
            <child link="calf_${leg_no}"/>
            <axis xyz="0 0 1"/>
            <!-- <limit lower="-3.14159" upper="3.14159" velocity="50.0" effort="1000.0"/> -->
            <limit effort="5" velocity="1.0" lower="-3.14159" upper="3.14159"/>

            <origin xyz="6 0 0" rpy="0 0 0"/>
        </joint> 
        <joint name="ankle_${leg_no}" type="revolute">
            <parent link="calf_${leg_no}"/>
            <child link="foot_${leg_no}"/>
            <axis xyz="0 0 1"/>
            <limit effort="5" velocity="1.0" lower="-3.14159" upper="3.14159"/>
            <origin xyz="4 0 0" rpy="0 0 0"/>
        </joint> 
        <!-- Transmissions -->
        <transmission name="hip_trans_${leg_no}">
            <type>transmission_interface/SimpleTransmission</type>
            <actuator name="hip_motor_${leg_no}">
            <mechanicalReduction>1</mechanicalReduction>
            </actuator>
            <joint name="hip_${leg_no}">
            <hardwareInterface>hardware_interface/PositionJointInterface</hardwareInterface>
            </joint>
        </transmission>
        <transmission name="knee_trans_${leg_no}">
            <type>transmission_interface/SimpleTransmission</type>
            <actuator name="knee_motor_${leg_no}">
            <mechanicalReduction>1</mechanicalReduction>
            </actuator>
            <joint name="knee_${leg_no}">
            <hardwareInterface>hardware_interface/PositionJointInterface</hardwareInterface>
            </joint>
        </transmission>
        <transmission name="ankle_trans_${leg_no}">
            <type>transmission_interface/SimpleTransmission</type>
            <actuator name="ankle_motor_${leg_no}">
            <mechanicalReduction>1</mechanicalReduction>
            </actuator>
            <joint name="ankle_${leg_no}">
            <hardwareInterface>hardware_interface/PositionJointInterface</hardwareInterface>
            </joint>
        </transmission>
        <!-- Links -->
        <link name="thigh_${leg_no}">
            <collision>
                <origin xyz="3 0 0" rpy="0 1.57 0"/>
                <geometry>
                    <cylinder radius="0.25" length="6"/>
                </geometry>
            </collision>
            <visual>
                <origin xyz="3 0 0" rpy="0 1.57 0"/>
                <geometry>
                    <cylinder radius="0.25" length="6"/>
                </geometry>
            </visual>
            <inertial>
                <mass value="10"/>
                <inertia ixx="1" ixy="0" ixz="0" iyy="1" iyz="0" izz="1"/>
            </inertial>
        </link>
        <link name="calf_${leg_no}">
            <collision>
                <origin xyz="2 0 0.0" rpy="0 1.57 0.0"/>
                <geometry>
                    <cylinder radius="0.25" length="4"/>
                </geometry>
            </collision>
            <visual>
                <origin xyz="2 0 0.0" rpy="0 1.57 0.0"/>
                <geometry>
                    <cylinder radius="0.25" length="4"/>
                </geometry>
            </visual>
            <visual>
                <origin xyz="0 0 0.0" rpy="0.0 0.0 0.0"/>
                
                <geometry>
                    <sphere radius="0.5"/>
                </geometry>
            </visual>
            <inertial>
                <mass value="10"/>
                <inertia ixx="1" ixy="0" ixz="0" iyy="1" iyz="0" izz="1"/>
            </inertial>
        </link>
        <link name="foot_${leg_no}">
            <collision>
                <origin xyz="1 0 0.0" rpy="0.0 1.57 0.0"/>
                <geometry>
                    <cylinder radius="0.25" length="2"/>
                </geometry>
            </collision>
            <visual>
                <origin xyz="1 0 0.0" rpy="0.0 1.57 0.0"/>
                <geometry>
                    <cylinder radius="0.25" length="2"/>
                </geometry>
            </visual>
            <visual>
                <origin xyz="0 0 0.0" rpy="0.0 0.0 0.0"/>
                
                <geometry>
                    <sphere radius="0.5"/>
                </geometry>
            </visual>
            <inertial>
                <mass value="10"/>
                <inertia ixx="1" ixy="0" ixz="0" iyy="1" iyz="0" izz="1"/>
            </inertial>
        </link>
        <gazebo reference="foot_${leg_no}">
            <mu1 value="200.0"/>
            <mu2 value="100.0"/>
            <kp value="10000000.0" />
            <kd value="1.0" />
            <material>Gazebo/Grey</material>
        </gazebo>
    </xacro:macro>
    <!-- fixed frame and link without xacro -->
    <link name="map"/>
    <joint name="fixed" type="fixed">
        <parent link="map"/>
        <child link="chassis"/>
        <origin xyz="0.0 0.0 0.0" rpy="1.57 0 0"/>
    </joint>   
    <link name="chassis">
        <collision>
            <origin xyz="0.0 0.0 0.0" rpy="0.0 0.0 0.0"/>
            <geometry>
                <box size="10.0 10.0 0.5"/>
            </geometry>
        </collision>
        <visual>
            <origin xyz="0.0 0.0 0.0" rpy="0.0 0.0 0.0"/>
            <geometry>
                <box size="10.0 0.5 10"/>
            </geometry>
        </visual>
        <inertial>
            <mass value="1000"/>
            <inertia ixx="100" ixy="0" ixz="0" iyy="100" iyz="0" izz="100"/>
        </inertial>
    </link>
    <!-- leg links with xacro -->
    <xacro:leg leg_no='1'>
        <origin xyz="-5 0 5" rpy="0 0 0"/>
    </xacro:leg>
    <xacro:leg leg_no='2'>
        <origin xyz="5 0 5" rpy="0 0 0"/>
    </xacro:leg>
    <xacro:leg leg_no='3'>
        <origin xyz="-5 0 -5" rpy="0 0 0"/>
    </xacro:leg>
    <xacro:leg leg_no='4'>
        <origin xyz="5 0 -5" rpy="0 0 0"/>
    </xacro:leg>

    <gazebo>
        <plugin name="gazebo_ros_control" filename="libgazebo_ros_control.so">
        <robotNamespace>/</robotNamespace>
        </plugin>
    </gazebo>
    
</robot>