<?xml version="1.0" ?>
<!-- =================================================================================== -->
<!-- |    This document was autogenerated by xacro from ele.xacro                      | -->
<!-- |    EDITING THIS FILE BY HAND IS NOT RECOMMENDED                                 | -->
<!-- =================================================================================== -->
<robot name="me">
  <!-- fixed frame and link without xacro -->
  <link name="map"/>
  <joint name="fixed" type="fixed">
    <parent link="map"/>
    <child link="chassis"/>
    <origin rpy="1.57 0 0" xyz="0.0 0.0 0.0"/>
  </joint>
  <link name="chassis">
    <collision>
      <origin rpy="0.0 0.0 0.0" xyz="0.0 0.0 0.0"/>
      <geometry>
        <box size="10.0 10.0 0.5"/>
      </geometry>
    </collision>
    <visual>
      <origin rpy="0.0 0.0 0.0" xyz="0.0 0.0 0.0"/>
      <geometry>
        <box size="10.0 0.5 10"/>
      </geometry>
    </visual>
    <inertial>
      <mass value="10"/>
      <inertia ixx="1" ixy="0" ixz="0" iyy="1" iyz="0" izz="1"/>
    </inertial>
  </link>
  <joint name="hip_1" type="continuous">
    <parent link="chassis"/>
    <child link="thigh_1"/>
    <axis xyz="0 0 1"/>
    <origin rpy="0 0 0" xyz="-5 0 5"/>
  </joint>
  <joint name="knee_1" type="revolute">
    <parent link="thigh_1"/>
    <child link="calf_1"/>
    <axis xyz="0 0 1"/>
    <limit effort="1000.0" lower="-3.14159" upper="3.14159" velocity="50.0"/>
    <origin rpy="0 0 0" xyz="0 -6 0"/>
  </joint>
  <joint name="ankle_1" type="revolute">
    <parent link="calf_1"/>
    <child link="foot_1"/>
    <axis xyz="0 0 1"/>
    <limit effort="1000.0" lower="-3.14159" upper="3.14159" velocity="50.0"/>
    <origin rpy="0 0 0" xyz="0 -4 0"/>
  </joint>
  <link name="thigh_1">
    <collision>
      <origin rpy="1.57 0.0 0.0" xyz="0.0 -3 0"/>
      <geometry>
        <cylinder length="6" radius="0.25"/>
      </geometry>
    </collision>
    <visual>
      <origin rpy="1.57 0.0 0" xyz="0.0 -3 0"/>
      <geometry>
        <cylinder length="6" radius="0.25"/>
      </geometry>
    </visual>
    <inertial>
      <mass value="10"/>
      <inertia ixx="1" ixy="0" ixz="0" iyy="1" iyz="0" izz="1"/>
    </inertial>
  </link>
  <link name="calf_1">
    <collision>
      <origin rpy="1.57 0.0 0.0" xyz="0.0 -2 0.0"/>
      <geometry>
        <cylinder length="4" radius="0.25"/>
      </geometry>
    </collision>
    <visual>
      <origin rpy="1.57 0.0 0.0" xyz="0.0 -2 0.0"/>
      <geometry>
        <cylinder length="4" radius="0.25"/>
      </geometry>
    </visual>
    <visual>
      <origin rpy="0.0 0.0 0.0" xyz="0 0 0.0"/>
      <geometry>
        <sphere radius="0.5"/>
      </geometry>
    </visual>
    <inertial>
      <mass value="10"/>
      <inertia ixx="1" ixy="0" ixz="0" iyy="1" iyz="0" izz="1"/>
    </inertial>
  </link>
  <link name="foot_1">
    <collision>
      <origin rpy="1.57 0.0 0.0" xyz="0.0 -1 0.0"/>
      <geometry>
        <cylinder length="2" radius="0.25"/>
      </geometry>
    </collision>
    <visual>
      <origin rpy="1.57 0.0 0.0" xyz="0.0 -1 0.0"/>
      <geometry>
        <cylinder length="2" radius="0.25"/>
      </geometry>
    </visual>
    <visual>
      <origin rpy="0.0 0.0 0.0" xyz="0 0 0.0"/>
      <geometry>
        <sphere radius="0.5"/>
      </geometry>
    </visual>
    <inertial>
      <mass value="10"/>
      <inertia ixx="1" ixy="0" ixz="0" iyy="1" iyz="0" izz="1"/>
    </inertial>
  </link>
  <!-- <xacro:leg leg_no='2'>
        <origin xyz="5 -5 0" rpy="-1.57 0 3.14"/>
    </xacro:leg>
    <xacro:leg leg_no='3'>
        <origin xyz="-5 -5 0" rpy="-1.57 0 3.14"/>
    </xacro:leg>
    <xacro:leg leg_no='4'>
        <origin xyz="-5 5 0" rpy="-1.57 0 3.14"/>
    </xacro:leg> -->
</robot>
