<?xml version="1.0" ?>
<!-- =================================================================================== -->
<!-- |    This document was autogenerated by xacro from quadra.xacro                   | -->
<!-- |    EDITING THIS FILE BY HAND IS NOT RECOMMENDED                                 | -->
<!-- =================================================================================== -->
<!-- URDF for connector -->
<robot name="me">
  <link name="chassis">
    <collision>
      <origin rpy="0.0 0.0 0.0" xyz="0.0 0.0 0.0"/>
      <geometry>
        <box size="10.0 10.0 0.5"/>
      </geometry>
    </collision>
    <visual>
      <origin rpy="0.0 0.0 0.0" xyz="0.0 0.0 0.0"/>
      <geometry>
        <box size="10.0 10.0 0.5"/>
      </geometry>
    </visual>
    <inertial>
      <mass value="10"/>
      <inertia ixx="1" ixy="0" ixz="0" iyy="1" iyz="0" izz="1"/>
    </inertial>
  </link>
  <joint name="rota_1" type="continuous">
    <parent link="chassis"/>
    <child link="leg_1"/>
    <axis xyz="0 0 1"/>
    <origin rpy="-1.57 0 3.14" xyz="5 5 0"/>
  </joint>
  <joint name="knee_1" type="revolute">
    <parent link="leg_1"/>
    <child link="ankle_1"/>
    <axis xyz="0 0 1"/>
    <limit effort="1000.0" lower="-3.14159" upper="3.14159" velocity="50.0"/>
    <origin rpy="0 0 0" xyz="0 4.5 0"/>
  </joint>
  <link name="leg_1">
    <collision>
      <origin rpy="1.57 0.0 0.0" xyz="0.0 2.5 0"/>
      <geometry>
        <cylinder length="5" radius="0.25"/>
      </geometry>
    </collision>
    <visual>
      <origin rpy="1.57 0.0 0" xyz="0.0 2.5 0"/>
      <geometry>
        <cylinder length="5" radius="0.25"/>
      </geometry>
    </visual>
    <inertial>
      <mass value="10"/>
      <inertia ixx="1" ixy="0" ixz="0" iyy="1" iyz="0" izz="1"/>
    </inertial>
  </link>
  <link name="ankle_1">
    <collision>
      <origin rpy="1.57 0.0 0.0" xyz="0.0 2.5 0.0"/>
      <geometry>
        <cylinder length="5" radius="0.25"/>
      </geometry>
    </collision>
    <visual>
      <origin rpy="1.57 0.0 0.0" xyz="0.0 2.5 0.0"/>
      <geometry>
        <cylinder length="5" radius="0.25"/>
      </geometry>
    </visual>
    <visual>
      <origin rpy="0.0 0.0 0.0" xyz="0 0 0.0"/>
      <geometry>
        <sphere radius="0.5"/>
      </geometry>
    </visual>
    <inertial>
      <mass value="10"/>
      <inertia ixx="1" ixy="0" ixz="0" iyy="1" iyz="0" izz="1"/>
    </inertial>
  </link>
  <joint name="rota_2" type="continuous">
    <parent link="chassis"/>
    <child link="leg_2"/>
    <axis xyz="0 0 1"/>
    <origin rpy="-1.57 0 3.14" xyz="5 -5 0"/>
  </joint>
  <joint name="knee_2" type="revolute">
    <parent link="leg_2"/>
    <child link="ankle_2"/>
    <axis xyz="0 0 1"/>
    <limit effort="1000.0" lower="-3.14159" upper="3.14159" velocity="50.0"/>
    <origin rpy="0 0 0" xyz="0 4.5 0"/>
  </joint>
  <link name="leg_2">
    <collision>
      <origin rpy="1.57 0.0 0.0" xyz="0.0 2.5 0"/>
      <geometry>
        <cylinder length="5" radius="0.25"/>
      </geometry>
    </collision>
    <visual>
      <origin rpy="1.57 0.0 0" xyz="0.0 2.5 0"/>
      <geometry>
        <cylinder length="5" radius="0.25"/>
      </geometry>
    </visual>
    <inertial>
      <mass value="10"/>
      <inertia ixx="1" ixy="0" ixz="0" iyy="1" iyz="0" izz="1"/>
    </inertial>
  </link>
  <link name="ankle_2">
    <collision>
      <origin rpy="1.57 0.0 0.0" xyz="0.0 2.5 0.0"/>
      <geometry>
        <cylinder length="5" radius="0.25"/>
      </geometry>
    </collision>
    <visual>
      <origin rpy="1.57 0.0 0.0" xyz="0.0 2.5 0.0"/>
      <geometry>
        <cylinder length="5" radius="0.25"/>
      </geometry>
    </visual>
    <visual>
      <origin rpy="0.0 0.0 0.0" xyz="0 0 0.0"/>
      <geometry>
        <sphere radius="0.5"/>
      </geometry>
    </visual>
    <inertial>
      <mass value="10"/>
      <inertia ixx="1" ixy="0" ixz="0" iyy="1" iyz="0" izz="1"/>
    </inertial>
  </link>
  <joint name="rota_3" type="continuous">
    <parent link="chassis"/>
    <child link="leg_3"/>
    <axis xyz="0 0 1"/>
    <origin rpy="-1.57 0 3.14" xyz="-5 -5 0"/>
  </joint>
  <joint name="knee_3" type="revolute">
    <parent link="leg_3"/>
    <child link="ankle_3"/>
    <axis xyz="0 0 1"/>
    <limit effort="1000.0" lower="-3.14159" upper="3.14159" velocity="50.0"/>
    <origin rpy="0 0 0" xyz="0 4.5 0"/>
  </joint>
  <link name="leg_3">
    <collision>
      <origin rpy="1.57 0.0 0.0" xyz="0.0 2.5 0"/>
      <geometry>
        <cylinder length="5" radius="0.25"/>
      </geometry>
    </collision>
    <visual>
      <origin rpy="1.57 0.0 0" xyz="0.0 2.5 0"/>
      <geometry>
        <cylinder length="5" radius="0.25"/>
      </geometry>
    </visual>
    <inertial>
      <mass value="10"/>
      <inertia ixx="1" ixy="0" ixz="0" iyy="1" iyz="0" izz="1"/>
    </inertial>
  </link>
  <link name="ankle_3">
    <collision>
      <origin rpy="1.57 0.0 0.0" xyz="0.0 2.5 0.0"/>
      <geometry>
        <cylinder length="5" radius="0.25"/>
      </geometry>
    </collision>
    <visual>
      <origin rpy="1.57 0.0 0.0" xyz="0.0 2.5 0.0"/>
      <geometry>
        <cylinder length="5" radius="0.25"/>
      </geometry>
    </visual>
    <visual>
      <origin rpy="0.0 0.0 0.0" xyz="0 0 0.0"/>
      <geometry>
        <sphere radius="0.5"/>
      </geometry>
    </visual>
    <inertial>
      <mass value="10"/>
      <inertia ixx="1" ixy="0" ixz="0" iyy="1" iyz="0" izz="1"/>
    </inertial>
  </link>
  <joint name="rota_4" type="continuous">
    <parent link="chassis"/>
    <child link="leg_4"/>
    <axis xyz="0 0 1"/>
    <origin rpy="-1.57 0 3.14" xyz="-5 5 0"/>
  </joint>
  <joint name="knee_4" type="revolute">
    <parent link="leg_4"/>
    <child link="ankle_4"/>
    <axis xyz="0 0 1"/>
    <limit effort="1000.0" lower="-3.14159" upper="3.14159" velocity="50.0"/>
    <origin rpy="0 0 0" xyz="0 4.5 0"/>
  </joint>
  <link name="leg_4">
    <collision>
      <origin rpy="1.57 0.0 0.0" xyz="0.0 2.5 0"/>
      <geometry>
        <cylinder length="5" radius="0.25"/>
      </geometry>
    </collision>
    <visual>
      <origin rpy="1.57 0.0 0" xyz="0.0 2.5 0"/>
      <geometry>
        <cylinder length="5" radius="0.25"/>
      </geometry>
    </visual>
    <inertial>
      <mass value="10"/>
      <inertia ixx="1" ixy="0" ixz="0" iyy="1" iyz="0" izz="1"/>
    </inertial>
  </link>
  <link name="ankle_4">
    <collision>
      <origin rpy="1.57 0.0 0.0" xyz="0.0 2.5 0.0"/>
      <geometry>
        <cylinder length="5" radius="0.25"/>
      </geometry>
    </collision>
    <visual>
      <origin rpy="1.57 0.0 0.0" xyz="0.0 2.5 0.0"/>
      <geometry>
        <cylinder length="5" radius="0.25"/>
      </geometry>
    </visual>
    <visual>
      <origin rpy="0.0 0.0 0.0" xyz="0 0 0.0"/>
      <geometry>
        <sphere radius="0.5"/>
      </geometry>
    </visual>
    <inertial>
      <mass value="10"/>
      <inertia ixx="1" ixy="0" ixz="0" iyy="1" iyz="0" izz="1"/>
    </inertial>
  </link>
</robot>

