<?xml version="1.0"?>
<robot xmlns:xacro="http://www.ros.org/wiki/xacro" name="me">
    
    <!-- Xacro defn for a leg -->
    <xacro:macro name="leg" params="leg_no *origin">
        <joint name="rota_${leg_no}" type="continuous">
            <parent link="chassis"/>
            <child link="leg_${leg_no}"/>
            <axis xyz="0 0 1"/>
            <xacro:insert_block name="origin" />
        </joint>
        <joint name="knee_${leg_no}" type="revolute">
            <parent link="leg_${leg_no}"/>
            <child link="ankle_${leg_no}"/>
            <axis xyz="0 0 1"/>
            <limit lower="-3.14159" upper="3.14159" velocity="50.0" effort="1000.0"/>
            <origin xyz="0 4.5 0" rpy="0 0 0"/>
        </joint> 
        <link name="leg_${leg_no}">
            <collision>
                <origin xyz="0.0 2.5 0" rpy="1.57 0.0 0.0"/>
                <geometry>
                    <cylinder radius="0.25" length="5"/>
                </geometry>
            </collision>
            <visual>
                <origin xyz="0.0 2.5 0" rpy="1.57 0.0 0"/>
                <geometry>
                    <cylinder radius="0.25" length="5"/>
                </geometry>
            </visual>
            <inertial>
                <mass value="10"/>
                <inertia ixx="1" ixy="0" ixz="0" iyy="1" iyz="0" izz="1"/>
            </inertial>
        </link>
        <link name="ankle_${leg_no}">
            <collision>
                <origin xyz="0.0 2.5 0.0" rpy="1.57 0.0 0.0"/>
                <geometry>
                    <cylinder radius="0.25" length="5"/>
                </geometry>
            </collision>
            <visual>
                <origin xyz="0.0 2.5 0.0" rpy="1.57 0.0 0.0"/>
                <geometry>
                    <cylinder radius="0.25" length="5"/>
                </geometry>
            </visual>
            <visual>
                <origin xyz="0 0 0.0" rpy="0.0 0.0 0.0"/>
                
                <geometry>
                    <sphere radius="0.5"/>
                </geometry>
            </visual>
            <inertial>
                <mass value="10"/>
                <inertia ixx="1" ixy="0" ixz="0" iyy="1" iyz="0" izz="1"/>
            </inertial>
        </link>
    </xacro:macro>
    <!-- fixed frame and link without xacro -->
    <link name="map"/>
    <joint name="fixed" type="fixed">
        <parent link="map"/>
        <child link="chassis"/>
        <origin xyz="0.0 0.0 0.0" rpy="0.0 0.0 0.0"/>
    </joint>   
    <link name="chassis">
        <collision>
            <origin xyz="0.0 0.0 0.0" rpy="0.0 0.0 0.0"/>
            <geometry>
                <box size="10.0 10.0 0.5"/>
            </geometry>
        </collision>
        <visual>
            <origin xyz="0.0 0.0 0.0" rpy="0.0 0.0 0.0"/>
            <geometry>
                <box size="10.0 10.0 0.5"/>
            </geometry>
        </visual>
        <inertial>
            <mass value="10"/>
            <inertia ixx="1" ixy="0" ixz="0" iyy="1" iyz="0" izz="1"/>
        </inertial>
    </link>
    <!-- leg links with xacro -->
    <xacro:leg leg_no='1'>
        <origin xyz="5 5 0" rpy="-1.57 0 3.14"/>
    </xacro:leg>
    <xacro:leg leg_no='2'>
        <origin xyz="5 -5 0" rpy="-1.57 0 3.14"/>
    </xacro:leg>
    <xacro:leg leg_no='3'>
        <origin xyz="-5 -5 0" rpy="-1.57 0 3.14"/>
    </xacro:leg>
    <xacro:leg leg_no='4'>
        <origin xyz="-5 5 0" rpy="-1.57 0 3.14"/>
    </xacro:leg>
    
</robot>